Workbook

Sheet 项目特征
A1: 规模计数时机 | C1: 估算中期 | D1: =IF(项目特征!C1='模板使用说明&基础参数'!H51,'模板使用说明&基础参数'!I51,IF(项目特征!C1='模板使用说明&基础参数'!H52,'模板使用说明&基础参数'!I52,IF(项目特征!C1='模板使用说明&基础参数'!H53,'模板使用说明&基础参数'!I53,IF(项目特征!C1='模板使用说明&基础参数'!H54,'模板使用说明&基础参数'!I54,1)))) -> 1.21
A2: 应用类型 | C2: 业务处理 | D2: =IF(C2='模板使用说明&基础参数'!G10,'模板使用说明&基础参数'!I10,IF(C2='模板使用说明&基础参数'!G11,'模板使用说明&基础参数'!I11,IF(C2='模板使用说明&基础参数'!G12,'模板使用说明&基础参数'!I12,IF(C2='模板使用说明&基础参数'!G13,'模板使用说明&基础参数'!I13,IF(C2='模板使用说明&基础参数'!G14,'模板使用说明&基础参数'!I14,IF(C2='模板使用说明&基础参数'!G15,'模板使用说明&基础参数'!I15,IF(C2='模板使用说明&基础参数'!G16,'模板使用说明&基础参数'!I16,IF(C2='模板使用说明&基础参数'!G17,'模板使用说明&基础参数'!I17,1)))))))) -> 1
A3: 质量特性 | B3: 分布式处理 | C3: 通过网络进行客户端/服务器及网络基础应用分布处理和传输 | D3: =IF(C3='模板使用说明&基础参数'!H20,'模板使用说明&基础参数'!I20,IF(C3='模板使用说明&基础参数'!H21,'模板使用说明&基础参数'!I21,IF(C3='模板使用说明&基础参数'!H22,'模板使用说明&基础参数'!I22,0))) -> 0
B4: 性能 | C4: 应答时间或处理率对高峰时间或所有业务时间来说都很重要，存在对连动系统结束处理时间的限制 | D4: =IF(C4='模板使用说明&基础参数'!H23,'模板使用说明&基础参数'!I23,IF(C4='模板使用说明&基础参数'!H24,'模板使用说明&基础参数'!I24,IF(C4='模板使用说明&基础参数'!H25,'模板使用说明&基础参数'!I25,0))) -> 0
B5: 可靠性 | C5: 发生故障时带来较多不便或经济损失 | D5: =IF(C5='模板使用说明&基础参数'!H26,'模板使用说明&基础参数'!I26,IF(C5='模板使用说明&基础参数'!H27,'模板使用说明&基础参数'!I27,IF(C5='模板使用说明&基础参数'!H28,'模板使用说明&基础参数'!I28,0))) -> 0
B6: 多重站点 | C6: 在设计阶段需要考虑不同站点的相似硬件或软件环境下运行需求 | D6: =IF(C6='模板使用说明&基础参数'!H29,'模板使用说明&基础参数'!I29,IF(C6='模板使用说明&基础参数'!H30,'模板使用说明&基础参数'!I30,IF(C6='模板使用说明&基础参数'!H31,'模板使用说明&基础参数'!I31,0))) -> 0
A7: 完整性级别 | C7: 没有明确的完整性级别或等级为C/D | D7: =IF(C7='模板使用说明&基础参数'!H46,'模板使用说明&基础参数'!I46,IF(C7='模板使用说明&基础参数'!H47,'模板使用说明&基础参数'!I47,IF(C7='模板使用说明&基础参数'!H48,'模板使用说明&基础参数'!I48,1))) -> 1
A8: 开发语言 | C8: JAVA、C++、C#及其他同级别语言/平台 | D8: =IF(C8='模板使用说明&基础参数'!H35,'模板使用说明&基础参数'!I35,IF(C8='模板使用说明&基础参数'!H36,'模板使用说明&基础参数'!I36,IF(C8='模板使用说明&基础参数'!H37,'模板使用说明&基础参数'!I37,1))) -> 1
A9: 开发团队背景 | C9: 为本行业开发过类似的软件 | D9: =IF(C9='模板使用说明&基础参数'!H41,'模板使用说明&基础参数'!I41,IF(C9='模板使用说明&基础参数'!H42,'模板使用说明&基础参数'!I42,IF(C9='模板使用说明&基础参数'!H43,'模板使用说明&基础参数'!I43,1))) -> 0.8

Sheet 规模估算
A1: 规模估算方法 | C1: 估算功能点 | D1: 请选择规模估算方法，缺省为“估算功能点”
A2: 功能点合计 | C2: =J54 -> 234 | D2: 单位：FP
A3: 调整后功能点 | C3: =M54 -> 105.06667 | D3: 单位：FP
A5: 编号 | B5: 涉及系统名称 | C5: 一级模块 | D5: 二级模块 | E5: 三级模块 | F5: 四级模块 | G5: 功能项描述 | H5: 功能点计数项名称 | I5: 类别 | J5: UFP | K5: 重用程度 | L5: 修改类型 | M5: US | N5: 备注
A6: =ROW()-5 -> 1 | B6: 新一代电子票据系统 | C6: 票据系统新增票据标识录入功能 | G6: 票据系统新增承兑申请票据标识录入功能，在信贷发起承兑申请批次时，票据系统收到承兑申请批次信息，在挑票前，可以对该承兑批次的票据进行票据标识录入 | H6: 承兑申请票据标识录入 | I6: EI | J6: =IF(I6="ILF",IF($C$1="预估功能点",'模板使用说明&基础参数'!$E$15,'模板使用说明&基础参数'!$E$22),IF(I6="EIF",IF($C$1="预估功能点",'模板使用说明&基础参数'!$E$16,'模板使用说明&基础参数'!$E$23),IF(I6="EI",IF($C$1="预估功能点",'模板使用说明&基础参数'!$E$17,'模板使用说明&基础参数'!$E$24),IF(I6="EO",IF($C$1="预估功能点",'模板使用说明&基础参数'!$E$18,'模板使用说明&基础参数'!$E$25),IF(I6="EQ",IF($C$1="预估功能点",'模板使用说明&基础参数'!$E$19,'模板使用说明&基础参数'!$E$26),""))))) -> 4 | K6: 中 | L6: 新增 | M6: =IF(J6="","",IF(K6="高",IF(L6="删除",J6*'模板使用说明&基础参数'!$E$5*'模板使用说明&基础参数'!$E$12,IF(L6="修改",J6*'模板使用说明&基础参数'!$E$5*'模板使用说明&基础参数'!$E$11,J6*'模板使用说明&基础参数'!$E$5*'模板使用说明&基础参数'!$E$10)),IF(K6="中",IF(L6="删除",J6*'模板使用说明&基础参数'!$E$6*'模板使用说明&基础参数'!$E$12,IF(L6="修改",J6*'模板使用说明&基础参数'!$E$6*'模板使用说明&基础参数'!$E$11,J6*'模板使用说明&基础参数'!$E$6*'模板使用说明&基础参数'!$E$10)),IF(L6="删除",J6*'模板使用说明&基础参数'!$E$7*'模板使用说明&基础参数'!$E$12,IF(L6="修改",J6*'模板使用说明&基础参数'!$E$7*'模板使用说明&基础参数'!$E$11,J6*'模板使用说明&基础参数'!$E$7*'模板使用说明&基础参数'!$E$10))))) -> 2.6666667
A7: =ROW()-5 -> 2 | G7: 承兑批次表增加票据标识字段 | H7: 承兑申请票据信息 | I7: ILF | J7: =IF(I7="ILF",IF($C$1="预估功能点",'模板使用说明&基础参数'!$E$15,'模板使用说明&基础参数'!$E$22),IF(I7="EIF",IF($C$1="预估功能点",'模板使用说明&基础参数'!$E$16,'模板使用说明&基础参数'!$E$23),IF(I7="EI",IF($C$1="预估功能点",'模板使用说明&基础参数'!$E$17,'模板使用说明&基础参数'!$E$24),IF(I7="EO",IF($C$1="预估功能点",'模板使用说明&基础参数'!$E$18,'模板使用说明&基础参数'!$E$25),IF(I7="EQ",IF($C$1="预估功能点",'模板使用说明&基础参数'!$E$19,'模板使用说明&基础参数'!$E$26),""))))) -> 10 | K7: 高 | L7: 修改 | M7: =IF(J7="","",IF(K7="高",IF(L7="删除",J7*'模板使用说明&基础参数'!$E$5*'模板使用说明&基础参数'!$E$12,IF(L7="修改",J7*'模板使用说明&基础参数'!$E$5*'模板使用说明&基础参数'!$E$11,J7*'模板使用说明&基础参数'!$E$5*'模板使用说明&基础参数'!$E$10)),IF(K7="中",IF(L7="删除",J7*'模板使用说明&基础参数'!$E$6*'模板使用说明&基础参数'!$E$12,IF(L7="修改",J7*'模板使用说明&基础参数'!$E$6*'模板使用说明&基础参数'!$E$11,J7*'模板使用说明&基础参数'!$E$6*'模板使用说明&基础参数'!$E$10)),IF(L7="删除",J7*'模板使用说明&基础参数'!$E$7*'模板使用说明&基础参数'!$E$12,IF(L7="修改",J7*'模板使用说明&基础参数'!$E$7*'模板使用说明&基础参数'!$E$11,J7*'模板使用说明&基础参数'!$E$7*'模板使用说明&基础参数'!$E$10))))) -> 2.6666667
A8: =ROW()-5 -> 3 | G8: 增加票据号码映射票据标识表，对打标的票据标识数据进行保存 | J8: =IF(I8="ILF",IF($C$1="预估功能点",'模板使用说明&基础参数'!$E$15,'模板使用说明&基础参数'!$E$22),IF(I8="EIF",IF($C$1="预估功能点",'模板使用说明&基础参数'!$E$16,'模板使用说明&基础参数'!$E$23),IF(I8="EI",IF($C$1="预估功能点",'模板使用说明&基础参数'!$E$17,'模板使用说明&基础参数'!$E$24),IF(I8="EO",IF($C$1="预估功能点",'模板使用说明&基础参数'!$E$18,'模板使用说明&基础参数'!$E$25),IF(I8="EQ",IF($C$1="预估功能点",'模板使用说明&基础参数'!$E$19,'模板使用说明&基础参数'!$E$26),""))))) | M8: =IF(J8="","",IF(K8="高",IF(L8="删除",J8*'模板使用说明&基础参数'!$E$5*'模板使用说明&基础参数'!$E$12,IF(L8="修改",J8*'模板使用说明&基础参数'!$E$5*'模板使用说明&基础参数'!$E$11,J8*'模板使用说明&基础参数'!$E$5*'模板使用说明&基础参数'!$E$10)),IF(K8="中",IF(L8="删除",J8*'模板使用说明&基础参数'!$E$6*'模板使用说明&基础参数'!$E$12,IF(L8="修改",J8*'模板使用说明&基础参数'!$E$6*'模板使用说明&基础参数'!$E$11,J8*'模板使用说明&基础参数'!$E$6*'模板使用说明&基础参数'!$E$10)),IF(L8="删除",J8*'模板使用说明&基础参数'!$E$7*'模板使用说明&基础参数'!$E$12,IF(L8="修改",J8*'模板使用说明&基础参数'!$E$7*'模板使用说明&基础参数'!$E$11,J8*'模板使用说明&基础参数'!$E$7*'模板使用说明&基础参数'!$E$10))))) | N8: 已识别
A9: =ROW()-5 -> 4 | C9: 票据系统新增票据标识接口 | G9: 票据系统新增票据标识接口，只有客户在网银做完贴现申请后，信贷根据票据维度向票据系统发起请求，查询票据的票据标识信息，票据系统将票交所返回的“科技(科技型企业)”标识返回给信贷系统 | H9: 票据标识信息查询 | I9: EQ | J9: =IF(I9="ILF",IF($C$1="预估功能点",'模板使用说明&基础参数'!$E$15,'模板使用说明&基础参数'!$E$22),IF(I9="EIF",IF($C$1="预估功能点",'模板使用说明&基础参数'!$E$16,'模板使用说明&基础参数'!$E$23),IF(I9="EI",IF($C$1="预估功能点",'模板使用说明&基础参数'!$E$17,'模板使用说明&基础参数'!$E$24),IF(I9="EO",IF($C$1="预估功能点",'模板使用说明&基础参数'!$E$18,'模板使用说明&基础参数'!$E$25),IF(I9="EQ",IF($C$1="预估功能点",'模板使用说明&基础参数'!$E$19,'模板使用说明&基础参数'!$E$26),""))))) -> 4 | K9: 中 | L9: 新增 | M9: =IF(J9="","",IF(K9="高",IF(L9="删除",J9*'模板使用说明&基础参数'!$E$5*'模板使用说明&基础参数'!$E$12,IF(L9="修改",J9*'模板使用说明&基础参数'!$E$5*'模板使用说明&基础参数'!$E$11,J9*'模板使用说明&基础参数'!$E$5*'模板使用说明&基础参数'!$E$10)),IF(K9="中",IF(L9="删除",J9*'模板使用说明&基础参数'!$E$6*'模板使用说明&基础参数'!$E$12,IF(L9="修改",J9*'模板使用说明&基础参数'!$E$6*'模板使用说明&基础参数'!$E$11,J9*'模板使用说明&基础参数'!$E$6*'模板使用说明&基础参数'!$E$10)),IF(L9="删除",J9*'模板使用说明&基础参数'!$E$7*'模板使用说明&基础参数'!$E$12,IF(L9="修改",J9*'模板使用说明&基础参数'!$E$7*'模板使用说明&基础参数'!$E$11,J9*'模板使用说明&基础参数'!$E$7*'模板使用说明&基础参数'!$E$10))))) -> 2.6666667
A10: =ROW()-5 -> 5 | C10: 票据系统新增票据标识结果返回接口 | G10: 票据系统新增票据标识结果返回接口，客户经理在票据系统做完承兑记账后，记账成功且签收成功后，票据系统根据票据维度将将票交所返回的“科技(科技型企业)”标识返回给信贷系统 | H10: 票据标识结果返回 | I10: EQ | J10: =IF(I10="ILF",IF($C$1="预估功能点",'模板使用说明&基础参数'!$E$15,'模板使用说明&基础参数'!$E$22),IF(I10="EIF",IF($C$1="预估功能点",'模板使用说明&基础参数'!$E$16,'模板使用说明&基础参数'!$E$23),IF(I10="EI",IF($C$1="预估功能点",'模板使用说明&基础参数'!$E$17,'模板使用说明&基础参数'!$E$24),IF(I10="EO",IF($C$1="预估功能点",'模板使用说明&基础参数'!$E$18,'模板使用说明&基础参数'!$E$25),IF(I10="EQ",IF($C$1="预估功能点",'模板使用说明&基础参数'!$E$19,'模板使用说明&基础参数'!$E$26),""))))) -> 4 | K10: 中 | L10: 新增 | M10: =IF(J10="","",IF(K10="高",IF(L10="删除",J10*'模板使用说明&基础参数'!$E$5*'模板使用说明&基础参数'!$E$12,IF(L10="修改",J10*'模板使用说明&基础参数'!$E$5*'模板使用说明&基础参数'!$E$11,J10*'模板使用说明&基础参数'!$E$5*'模板使用说明&基础参数'!$E$10)),IF(K10="中",IF(L10="删除",J10*'模板使用说明&基础参数'!$E$6*'模板使用说明&基础参数'!$E$12,IF(L10="修改",J10*'模板使用说明&基础参数'!$E$6*'模板使用说明&基础参数'!$E$11,J10*'模板使用说明&基础参数'!$E$6*'模板使用说明&基础参数'!$E$10)),IF(L10="删除",J10*'模板使用说明&基础参数'!$E$7*'模板使用说明&基础参数'!$E$12,IF(L10="修改",J10*'模板使用说明&基础参数'!$E$7*'模板使用说明&基础参数'!$E$11,J10*'模板使用说明&基础参数'!$E$7*'模板使用说明&基础参数'!$E$10))))) -> 2.6666667
A11: =ROW()-5 -> 6 | C11: 票据系统新增承兑票据标识修改功能 | G11: 票据系统新增承兑申请票据标识录入功能，在信贷发起承兑申请批次时，票据系统收到承兑申请批次信息，在挑票前，可以对该承兑批次录入的票据标识进行修改，同时支持出账后修改票据标识。“科技（科技型企业）”标识不可修改 | H11: 承兑申请票据信息修改 | I11: EI | J11: =IF(I11="ILF",IF($C$1="预估功能点",'模板使用说明&基础参数'!$E$15,'模板使用说明&基础参数'!$E$22),IF(I11="EIF",IF($C$1="预估功能点",'模板使用说明&基础参数'!$E$16,'模板使用说明&基础参数'!$E$23),IF(I11="EI",IF($C$1="预估功能点",'模板使用说明&基础参数'!$E$17,'模板使用说明&基础参数'!$E$24),IF(I11="EO",IF($C$1="预估功能点",'模板使用说明&基础参数'!$E$18,'模板使用说明&基础参数'!$E$25),IF(I11="EQ",IF($C$1="预估功能点",'模板使用说明&基础参数'!$E$19,'模板使用说明&基础参数'!$E$26),""))))) -> 4 | K11: 中 | L11: 新增 | M11: =IF(J11="","",IF(K11="高",IF(L11="删除",J11*'模板使用说明&基础参数'!$E$5*'模板使用说明&基础参数'!$E$12,IF(L11="修改",J11*'模板使用说明&基础参数'!$E$5*'模板使用说明&基础参数'!$E$11,J11*'模板使用说明&基础参数'!$E$5*'模板使用说明&基础参数'!$E$10)),IF(K11="中",IF(L11="删除",J11*'模板使用说明&基础参数'!$E$6*'模板使用说明&基础参数'!$E$12,IF(L11="修改",J11*'模板使用说明&基础参数'!$E$6*'模板使用说明&基础参数'!$E$11,J11*'模板使用说明&基础参数'!$E$6*'模板使用说明&基础参数'!$E$10)),IF(L11="删除",J11*'模板使用说明&基础参数'!$E$7*'模板使用说明&基础参数'!$E$12,IF(L11="修改",J11*'模板使用说明&基础参数'!$E$7*'模板使用说明&基础参数'!$E$11,J11*'模板使用说明&基础参数'!$E$7*'模板使用说明&基础参数'!$E$10))))) -> 2.6666667
A12: =ROW()-5 -> 7 | C12: 票据系统新增承兑票据标识删除功能 | G12: 票据系统新增承兑申请票据标识录入功能，在信贷发起承兑申请批次时，票据系统收到承兑申请批次信息，在挑票前，可以对该承兑批次录入的票据标识进行删除，同时支持出账后删除票据标识。“科技（科技型企业）”标识不可删除 | H12: 承兑申请票据信息删除 | I12: EI | J12: =IF(I12="ILF",IF($C$1="预估功能点",'模板使用说明&基础参数'!$E$15,'模板使用说明&基础参数'!$E$22),IF(I12="EIF",IF($C$1="预估功能点",'模板使用说明&基础参数'!$E$16,'模板使用说明&基础参数'!$E$23),IF(I12="EI",IF($C$1="预估功能点",'模板使用说明&基础参数'!$E$17,'模板使用说明&基础参数'!$E$24),IF(I12="EO",IF($C$1="预估功能点",'模板使用说明&基础参数'!$E$18,'模板使用说明&基础参数'!$E$25),IF(I12="EQ",IF($C$1="预估功能点",'模板使用说明&基础参数'!$E$19,'模板使用说明&基础参数'!$E$26),""))))) -> 4 | K12: 高 | L12: 新增 | M12: =IF(J12="","",IF(K12="高",IF(L12="删除",J12*'模板使用说明&基础参数'!$E$5*'模板使用说明&基础参数'!$E$12,IF(L12="修改",J12*'模板使用说明&基础参数'!$E$5*'模板使用说明&基础参数'!$E$11,J12*'模板使用说明&基础参数'!$E$5*'模板使用说明&基础参数'!$E$10)),IF(K12="中",IF(L12="删除",J12*'模板使用说明&基础参数'!$E$6*'模板使用说明&基础参数'!$E$12,IF(L12="修改",J12*'模板使用说明&基础参数'!$E$6*'模板使用说明&基础参数'!$E$11,J12*'模板使用说明&基础参数'!$E$6*'模板使用说明&基础参数'!$E$10)),IF(L12="删除",J12*'模板使用说明&基础参数'!$E$7*'模板使用说明&基础参数'!$E$12,IF(L12="修改",J12*'模板使用说明&基础参数'!$E$7*'模板使用说明&基础参数'!$E$11,J12*'模板使用说明&基础参数'!$E$7*'模板使用说明&基础参数'!$E$10))))) -> 1.3333333
A13: =ROW()-5 -> 8 | C13: 票据系统票据标识批量模板下载功能 | G13: 票据系统新增批量模板下载功能，提供给客户经理批量导入功能的模板 | H13: 票据标识批量模板下载 | I13: EQ | J13: =IF(I13="ILF",IF($C$1="预估功能点",'模板使用说明&基础参数'!$E$15,'模板使用说明&基础参数'!$E$22),IF(I13="EIF",IF($C$1="预估功能点",'模板使用说明&基础参数'!$E$16,'模板使用说明&基础参数'!$E$23),IF(I13="EI",IF($C$1="预估功能点",'模板使用说明&基础参数'!$E$17,'模板使用说明&基础参数'!$E$24),IF(I13="EO",IF($C$1="预估功能点",'模板使用说明&基础参数'!$E$18,'模板使用说明&基础参数'!$E$25),IF(I13="EQ",IF($C$1="预估功能点",'模板使用说明&基础参数'!$E$19,'模板使用说明&基础参数'!$E$26),""))))) -> 4 | K13: 中 | L13: 新增 | M13: =IF(J13="","",IF(K13="高",IF(L13="删除",J13*'模板使用说明&基础参数'!$E$5*'模板使用说明&基础参数'!$E$12,IF(L13="修改",J13*'模板使用说明&基础参数'!$E$5*'模板使用说明&基础参数'!$E$11,J13*'模板使用说明&基础参数'!$E$5*'模板使用说明&基础参数'!$E$10)),IF(K13="中",IF(L13="删除",J13*'模板使用说明&基础参数'!$E$6*'模板使用说明&基础参数'!$E$12,IF(L13="修改",J13*'模板使用说明&基础参数'!$E$6*'模板使用说明&基础参数'!$E$11,J13*'模板使用说明&基础参数'!$E$6*'模板使用说明&基础参数'!$E$10)),IF(L13="删除",J13*'模板使用说明&基础参数'!$E$7*'模板使用说明&基础参数'!$E$12,IF(L13="修改",J13*'模板使用说明&基础参数'!$E$7*'模板使用说明&基础参数'!$E$11,J13*'模板使用说明&基础参数'!$E$7*'模板使用说明&基础参数'!$E$10))))) -> 2.6666667
A14: =ROW()-5 -> 9 | C14: 票据系统票据标识批量导入功能 | G14: 票据系统新增承兑申请票据标识录入功能，在信贷发起承兑申请批次时，票据系统收到承兑申请批次信息，在挑票前，可以通过导入文件对该批次的票进行批量录入票据标识的功能 | H14: 票据标识批量导入 | I14: EI | J14: =IF(I14="ILF",IF($C$1="预估功能点",'模板使用说明&基础参数'!$E$15,'模板使用说明&基础参数'!$E$22),IF(I14="EIF",IF($C$1="预估功能点",'模板使用说明&基础参数'!$E$16,'模板使用说明&基础参数'!$E$23),IF(I14="EI",IF($C$1="预估功能点",'模板使用说明&基础参数'!$E$17,'模板使用说明&基础参数'!$E$24),IF(I14="EO",IF($C$1="预估功能点",'模板使用说明&基础参数'!$E$18,'模板使用说明&基础参数'!$E$25),IF(I14="EQ",IF($C$1="预估功能点",'模板使用说明&基础参数'!$E$19,'模板使用说明&基础参数'!$E$26),""))))) -> 4 | K14: 中 | L14: 新增 | M14: =IF(J14="","",IF(K14="高",IF(L14="删除",J14*'模板使用说明&基础参数'!$E$5*'模板使用说明&基础参数'!$E$12,IF(L14="修改",J14*'模板使用说明&基础参数'!$E$5*'模板使用说明&基础参数'!$E$11,J14*'模板使用说明&基础参数'!$E$5*'模板使用说明&基础参数'!$E$10)),IF(K14="中",IF(L14="删除",J14*'模板使用说明&基础参数'!$E$6*'模板使用说明&基础参数'!$E$12,IF(L14="修改",J14*'模板使用说明&基础参数'!$E$6*'模板使用说明&基础参数'!$E$11,J14*'模板使用说明&基础参数'!$E$6*'模板使用说明&基础参数'!$E$10)),IF(L14="删除",J14*'模板使用说明&基础参数'!$E$7*'模板使用说明&基础参数'!$E$12,IF(L14="修改",J14*'模板使用说明&基础参数'!$E$7*'模板使用说明&基础参数'!$E$11,J14*'模板使用说明&基础参数'!$E$7*'模板使用说明&基础参数'!$E$10))))) -> 2.6666667
A15: =ROW()-5 -> 10 | C15: 票据系统新增承兑票据标识登记申请功能 | G15: 票据系统新增承兑票据标识发送票交所登记申请功能，出票时票据标识登记申请随CIM017报文发送票交所 | H15: 承兑票据标识登记申请 | I15: EI | J15: =IF(I15="ILF",IF($C$1="预估功能点",'模板使用说明&基础参数'!$E$15,'模板使用说明&基础参数'!$E$22),IF(I15="EIF",IF($C$1="预估功能点",'模板使用说明&基础参数'!$E$16,'模板使用说明&基础参数'!$E$23),IF(I15="EI",IF($C$1="预估功能点",'模板使用说明&基础参数'!$E$17,'模板使用说明&基础参数'!$E$24),IF(I15="EO",IF($C$1="预估功能点",'模板使用说明&基础参数'!$E$18,'模板使用说明&基础参数'!$E$25),IF(I15="EQ",IF($C$1="预估功能点",'模板使用说明&基础参数'!$E$19,'模板使用说明&基础参数'!$E$26),""))))) -> 4 | K15: 中 | L15: 新增 | M15: =IF(J15="","",IF(K15="高",IF(L15="删除",J15*'模板使用说明&基础参数'!$E$5*'模板使用说明&基础参数'!$E$12,IF(L15="修改",J15*'模板使用说明&基础参数'!$E$5*'模板使用说明&基础参数'!$E$11,J15*'模板使用说明&基础参数'!$E$5*'模板使用说明&基础参数'!$E$10)),IF(K15="中",IF(L15="删除",J15*'模板使用说明&基础参数'!$E$6*'模板使用说明&基础参数'!$E$12,IF(L15="修改",J15*'模板使用说明&基础参数'!$E$6*'模板使用说明&基础参数'!$E$11,J15*'模板使用说明&基础参数'!$E$6*'模板使用说明&基础参数'!$E$10)),IF(L15="删除",J15*'模板使用说明&基础参数'!$E$7*'模板使用说明&基础参数'!$E$12,IF(L15="修改",J15*'模板使用说明&基础参数'!$E$7*'模板使用说明&基础参数'!$E$11,J15*'模板使用说明&基础参数'!$E$7*'模板使用说明&基础参数'!$E$10))))) -> 2.6666667
A16: =ROW()-5 -> 11 | C16: 票据系统新增承兑票据标识自动登记功能 | G16: 票据系统新增承兑票据标识自动登记功能，收到收票人签收报文后后自动登记票据标识功能、自动登记并发控制 | H16: 承兑票据标识自动登记 | I16: EI | J16: =IF(I16="ILF",IF($C$1="预估功能点",'模板使用说明&基础参数'!$E$15,'模板使用说明&基础参数'!$E$22),IF(I16="EIF",IF($C$1="预估功能点",'模板使用说明&基础参数'!$E$16,'模板使用说明&基础参数'!$E$23),IF(I16="EI",IF($C$1="预估功能点",'模板使用说明&基础参数'!$E$17,'模板使用说明&基础参数'!$E$24),IF(I16="EO",IF($C$1="预估功能点",'模板使用说明&基础参数'!$E$18,'模板使用说明&基础参数'!$E$25),IF(I16="EQ",IF($C$1="预估功能点",'模板使用说明&基础参数'!$E$19,'模板使用说明&基础参数'!$E$26),""))))) -> 4 | K16: 中 | L16: 新增 | M16: =IF(J16="","",IF(K16="高",IF(L16="删除",J16*'模板使用说明&基础参数'!$E$5*'模板使用说明&基础参数'!$E$12,IF(L16="修改",J16*'模板使用说明&基础参数'!$E$5*'模板使用说明&基础参数'!$E$11,J16*'模板使用说明&基础参数'!$E$5*'模板使用说明&基础参数'!$E$10)),IF(K16="中",IF(L16="删除",J16*'模板使用说明&基础参数'!$E$6*'模板使用说明&基础参数'!$E$12,IF(L16="修改",J16*'模板使用说明&基础参数'!$E$6*'模板使用说明&基础参数'!$E$11,J16*'模板使用说明&基础参数'!$E$6*'模板使用说明&基础参数'!$E$10)),IF(L16="删除",J16*'模板使用说明&基础参数'!$E$7*'模板使用说明&基础参数'!$E$12,IF(L16="修改",J16*'模板使用说明&基础参数'!$E$7*'模板使用说明&基础参数'!$E$11,J16*'模板使用说明&基础参数'!$E$7*'模板使用说明&基础参数'!$E$10))))) -> 2.6666667
A17: =ROW()-5 -> 12 | C17: 票据系统新增票据标识清退功能 | G17: 票据系统新增出票票据标识-清退处理功能，对于承兑拒绝、到期清退出票票据标识清退处理 | H17: 出票票据标识-清退处理 | I17: EI | J17: =IF(I17="ILF",IF($C$1="预估功能点",'模板使用说明&基础参数'!$E$15,'模板使用说明&基础参数'!$E$22),IF(I17="EIF",IF($C$1="预估功能点",'模板使用说明&基础参数'!$E$16,'模板使用说明&基础参数'!$E$23),IF(I17="EI",IF($C$1="预估功能点",'模板使用说明&基础参数'!$E$17,'模板使用说明&基础参数'!$E$24),IF(I17="EO",IF($C$1="预估功能点",'模板使用说明&基础参数'!$E$18,'模板使用说明&基础参数'!$E$25),IF(I17="EQ",IF($C$1="预估功能点",'模板使用说明&基础参数'!$E$19,'模板使用说明&基础参数'!$E$26),""))))) -> 4 | K17: 中 | L17: 新增 | M17: =IF(J17="","",IF(K17="高",IF(L17="删除",J17*'模板使用说明&基础参数'!$E$5*'模板使用说明&基础参数'!$E$12,IF(L17="修改",J17*'模板使用说明&基础参数'!$E$5*'模板使用说明&基础参数'!$E$11,J17*'模板使用说明&基础参数'!$E$5*'模板使用说明&基础参数'!$E$10)),IF(K17="中",IF(L17="删除",J17*'模板使用说明&基础参数'!$E$6*'模板使用说明&基础参数'!$E$12,IF(L17="修改",J17*'模板使用说明&基础参数'!$E$6*'模板使用说明&基础参数'!$E$11,J17*'模板使用说明&基础参数'!$E$6*'模板使用说明&基础参数'!$E$10)),IF(L17="删除",J17*'模板使用说明&基础参数'!$E$7*'模板使用说明&基础参数'!$E$12,IF(L17="修改",J17*'模板使用说明&基础参数'!$E$7*'模板使用说明&基础参数'!$E$11,J17*'模板使用说明&基础参数'!$E$7*'模板使用说明&基础参数'!$E$10))))) -> 2.6666667
A18: =ROW()-5 -> 13 | C18: 票据系统新增承兑票据标识跟踪查询功能 | G18: 票据系统新增承兑票据标识跟踪查询功能，票据标识跟踪界面-查询出票和贴现票据的票据标识 | H18: 承兑票据标识跟踪查询 | I18: EQ | J18: =IF(I18="ILF",IF($C$1="预估功能点",'模板使用说明&基础参数'!$E$15,'模板使用说明&基础参数'!$E$22),IF(I18="EIF",IF($C$1="预估功能点",'模板使用说明&基础参数'!$E$16,'模板使用说明&基础参数'!$E$23),IF(I18="EI",IF($C$1="预估功能点",'模板使用说明&基础参数'!$E$17,'模板使用说明&基础参数'!$E$24),IF(I18="EO",IF($C$1="预估功能点",'模板使用说明&基础参数'!$E$18,'模板使用说明&基础参数'!$E$25),IF(I18="EQ",IF($C$1="预估功能点",'模板使用说明&基础参数'!$E$19,'模板使用说明&基础参数'!$E$26),""))))) -> 4 | K18: 中 | L18: 新增 | M18: =IF(J18="","",IF(K18="高",IF(L18="删除",J18*'模板使用说明&基础参数'!$E$5*'模板使用说明&基础参数'!$E$12,IF(L18="修改",J18*'模板使用说明&基础参数'!$E$5*'模板使用说明&基础参数'!$E$11,J18*'模板使用说明&基础参数'!$E$5*'模板使用说明&基础参数'!$E$10)),IF(K18="中",IF(L18="删除",J18*'模板使用说明&基础参数'!$E$6*'模板使用说明&基础参数'!$E$12,IF(L18="修改",J18*'模板使用说明&基础参数'!$E$6*'模板使用说明&基础参数'!$E$11,J18*'模板使用说明&基础参数'!$E$6*'模板使用说明&基础参数'!$E$10)),IF(L18="删除",J18*'模板使用说明&基础参数'!$E$7*'模板使用说明&基础参数'!$E$12,IF(L18="修改",J18*'模板使用说明&基础参数'!$E$7*'模板使用说明&基础参数'!$E$11,J18*'模板使用说明&基础参数'!$E$7*'模板使用说明&基础参数'!$E$10))))) -> 2.6666667
A19: =ROW()-5 -> 14 | C19: 票据系统新增承兑票据标识自动报送定时任务 | G19: 在承兑签收后，票据系统新增定时任务对打标的票据信息实现自动报送票交所的功能 | H19: 承兑票据标识自动报送 | I19: EQ | J19: =IF(I19="ILF",IF($C$1="预估功能点",'模板使用说明&基础参数'!$E$15,'模板使用说明&基础参数'!$E$22),IF(I19="EIF",IF($C$1="预估功能点",'模板使用说明&基础参数'!$E$16,'模板使用说明&基础参数'!$E$23),IF(I19="EI",IF($C$1="预估功能点",'模板使用说明&基础参数'!$E$17,'模板使用说明&基础参数'!$E$24),IF(I19="EO",IF($C$1="预估功能点",'模板使用说明&基础参数'!$E$18,'模板使用说明&基础参数'!$E$25),IF(I19="EQ",IF($C$1="预估功能点",'模板使用说明&基础参数'!$E$19,'模板使用说明&基础参数'!$E$26),""))))) -> 4 | K19: 中 | L19: 新增 | M19: =IF(J19="","",IF(K19="高",IF(L19="删除",J19*'模板使用说明&基础参数'!$E$5*'模板使用说明&基础参数'!$E$12,IF(L19="修改",J19*'模板使用说明&基础参数'!$E$5*'模板使用说明&基础参数'!$E$11,J19*'模板使用说明&基础参数'!$E$5*'模板使用说明&基础参数'!$E$10)),IF(K19="中",IF(L19="删除",J19*'模板使用说明&基础参数'!$E$6*'模板使用说明&基础参数'!$E$12,IF(L19="修改",J19*'模板使用说明&基础参数'!$E$6*'模板使用说明&基础参数'!$E$11,J19*'模板使用说明&基础参数'!$E$6*'模板使用说明&基础参数'!$E$10)),IF(L19="删除",J19*'模板使用说明&基础参数'!$E$7*'模板使用说明&基础参数'!$E$12,IF(L19="修改",J19*'模板使用说明&基础参数'!$E$7*'模板使用说明&基础参数'!$E$11,J19*'模板使用说明&基础参数'!$E$7*'模板使用说明&基础参数'!$E$10))))) -> 2.6666667
A20: =ROW()-5 -> 15 | C20: 票据系统新增贴现出账申请接收票据标识功能 | G20: 票据系统新增信贷系统贴现出账申请接收票据标识功能，将信贷系统送过来的票据标识保存在票据系统，同时增加票据号码映射票据标识表，对打标的票据标识数据进行保存 | H20: 贴现出账申请接收 | I20: EI | J20: =IF(I20="ILF",IF($C$1="预估功能点",'模板使用说明&基础参数'!$E$15,'模板使用说明&基础参数'!$E$22),IF(I20="EIF",IF($C$1="预估功能点",'模板使用说明&基础参数'!$E$16,'模板使用说明&基础参数'!$E$23),IF(I20="EI",IF($C$1="预估功能点",'模板使用说明&基础参数'!$E$17,'模板使用说明&基础参数'!$E$24),IF(I20="EO",IF($C$1="预估功能点",'模板使用说明&基础参数'!$E$18,'模板使用说明&基础参数'!$E$25),IF(I20="EQ",IF($C$1="预估功能点",'模板使用说明&基础参数'!$E$19,'模板使用说明&基础参数'!$E$26),""))))) -> 4 | K20: 中 | L20: 新增 | M20: =IF(J20="","",IF(K20="高",IF(L20="删除",J20*'模板使用说明&基础参数'!$E$5*'模板使用说明&基础参数'!$E$12,IF(L20="修改",J20*'模板使用说明&基础参数'!$E$5*'模板使用说明&基础参数'!$E$11,J20*'模板使用说明&基础参数'!$E$5*'模板使用说明&基础参数'!$E$10)),IF(K20="中",IF(L20="删除",J20*'模板使用说明&基础参数'!$E$6*'模板使用说明&基础参数'!$E$12,IF(L20="修改",J20*'模板使用说明&基础参数'!$E$6*'模板使用说明&基础参数'!$E$11,J20*'模板使用说明&基础参数'!$E$6*'模板使用说明&基础参数'!$E$10)),IF(L20="删除",J20*'模板使用说明&基础参数'!$E$7*'模板使用说明&基础参数'!$E$12,IF(L20="修改",J20*'模板使用说明&基础参数'!$E$7*'模板使用说明&基础参数'!$E$11,J20*'模板使用说明&基础参数'!$E$7*'模板使用说明&基础参数'!$E$10))))) -> 2.6666667
A21: =ROW()-5 -> 16 | G21: 贴现批次表增加票据标识字段 | H21: 贴现批次信息 | I21: ILF | J21: =IF(I21="ILF",IF($C$1="预估功能点",'模板使用说明&基础参数'!$E$15,'模板使用说明&基础参数'!$E$22),IF(I21="EIF",IF($C$1="预估功能点",'模板使用说明&基础参数'!$E$16,'模板使用说明&基础参数'!$E$23),IF(I21="EI",IF($C$1="预估功能点",'模板使用说明&基础参数'!$E$17,'模板使用说明&基础参数'!$E$24),IF(I21="EO",IF($C$1="预估功能点",'模板使用说明&基础参数'!$E$18,'模板使用说明&基础参数'!$E$25),IF(I21="EQ",IF($C$1="预估功能点",'模板使用说明&基础参数'!$E$19,'模板使用说明&基础参数'!$E$26),""))))) -> 10 | K21: 高 | L21: 修改 | M21: =IF(J21="","",IF(K21="高",IF(L21="删除",J21*'模板使用说明&基础参数'!$E$5*'模板使用说明&基础参数'!$E$12,IF(L21="修改",J21*'模板使用说明&基础参数'!$E$5*'模板使用说明&基础参数'!$E$11,J21*'模板使用说明&基础参数'!$E$5*'模板使用说明&基础参数'!$E$10)),IF(K21="中",IF(L21="删除",J21*'模板使用说明&基础参数'!$E$6*'模板使用说明&基础参数'!$E$12,IF(L21="修改",J21*'模板使用说明&基础参数'!$E$6*'模板使用说明&基础参数'!$E$11,J21*'模板使用说明&基础参数'!$E$6*'模板使用说明&基础参数'!$E$10)),IF(L21="删除",J21*'模板使用说明&基础参数'!$E$7*'模板使用说明&基础参数'!$E$12,IF(L21="修改",J21*'模板使用说明&基础参数'!$E$7*'模板使用说明&基础参数'!$E$11,J21*'模板使用说明&基础参数'!$E$7*'模板使用说明&基础参数'!$E$10))))) -> 2.6666667
A22: =ROW()-5 -> 17 | C22: 票据系统新增贴现出账票据标识修改功能 | G22: 票据系统新增信贷系统贴现出账票据标识修改功能，在票据系统能支持票据标识修改功能 | H22: 贴现出账票据标识修改 | I22: EI | J22: =IF(I22="ILF",IF($C$1="预估功能点",'模板使用说明&基础参数'!$E$15,'模板使用说明&基础参数'!$E$22),IF(I22="EIF",IF($C$1="预估功能点",'模板使用说明&基础参数'!$E$16,'模板使用说明&基础参数'!$E$23),IF(I22="EI",IF($C$1="预估功能点",'模板使用说明&基础参数'!$E$17,'模板使用说明&基础参数'!$E$24),IF(I22="EO",IF($C$1="预估功能点",'模板使用说明&基础参数'!$E$18,'模板使用说明&基础参数'!$E$25),IF(I22="EQ",IF($C$1="预估功能点",'模板使用说明&基础参数'!$E$19,'模板使用说明&基础参数'!$E$26),""))))) -> 4 | K22: 中 | L22: 新增 | M22: =IF(J22="","",IF(K22="高",IF(L22="删除",J22*'模板使用说明&基础参数'!$E$5*'模板使用说明&基础参数'!$E$12,IF(L22="修改",J22*'模板使用说明&基础参数'!$E$5*'模板使用说明&基础参数'!$E$11,J22*'模板使用说明&基础参数'!$E$5*'模板使用说明&基础参数'!$E$10)),IF(K22="中",IF(L22="删除",J22*'模板使用说明&基础参数'!$E$6*'模板使用说明&基础参数'!$E$12,IF(L22="修改",J22*'模板使用说明&基础参数'!$E$6*'模板使用说明&基础参数'!$E$11,J22*'模板使用说明&基础参数'!$E$6*'模板使用说明&基础参数'!$E$10)),IF(L22="删除",J22*'模板使用说明&基础参数'!$E$7*'模板使用说明&基础参数'!$E$12,IF(L22="修改",J22*'模板使用说明&基础参数'!$E$7*'模板使用说明&基础参数'!$E$11,J22*'模板使用说明&基础参数'!$E$7*'模板使用说明&基础参数'!$E$10))))) -> 2.6666667
A23: =ROW()-5 -> 18 | C23: 票据系统新增贴现出账票据标识删除功能 | G23: 票据系统新增信贷系统贴现出账票据标识删除功能，在票据系统能支持票据标识修改功能 | H23: 贴现出账票据标识删除 | I23: EI | J23: =IF(I23="ILF",IF($C$1="预估功能点",'模板使用说明&基础参数'!$E$15,'模板使用说明&基础参数'!$E$22),IF(I23="EIF",IF($C$1="预估功能点",'模板使用说明&基础参数'!$E$16,'模板使用说明&基础参数'!$E$23),IF(I23="EI",IF($C$1="预估功能点",'模板使用说明&基础参数'!$E$17,'模板使用说明&基础参数'!$E$24),IF(I23="EO",IF($C$1="预估功能点",'模板使用说明&基础参数'!$E$18,'模板使用说明&基础参数'!$E$25),IF(I23="EQ",IF($C$1="预估功能点",'模板使用说明&基础参数'!$E$19,'模板使用说明&基础参数'!$E$26),""))))) -> 4 | K23: 高 | L23: 新增 | M23: =IF(J23="","",IF(K23="高",IF(L23="删除",J23*'模板使用说明&基础参数'!$E$5*'模板使用说明&基础参数'!$E$12,IF(L23="修改",J23*'模板使用说明&基础参数'!$E$5*'模板使用说明&基础参数'!$E$11,J23*'模板使用说明&基础参数'!$E$5*'模板使用说明&基础参数'!$E$10)),IF(K23="中",IF(L23="删除",J23*'模板使用说明&基础参数'!$E$6*'模板使用说明&基础参数'!$E$12,IF(L23="修改",J23*'模板使用说明&基础参数'!$E$6*'模板使用说明&基础参数'!$E$11,J23*'模板使用说明&基础参数'!$E$6*'模板使用说明&基础参数'!$E$10)),IF(L23="删除",J23*'模板使用说明&基础参数'!$E$7*'模板使用说明&基础参数'!$E$12,IF(L23="修改",J23*'模板使用说明&基础参数'!$E$7*'模板使用说明&基础参数'!$E$11,J23*'模板使用说明&基础参数'!$E$7*'模板使用说明&基础参数'!$E$10))))) -> 1.3333333
A24: =ROW()-5 -> 19 | C24: 票据系统新增贴现票据标识登记申请功能 | G24: 票据系统新增贴现票据标识发送票交所登记申请功能，出票时票据标识登记申请随CIM017报文发送票交所 | H24: 贴现票据标识登记申请 | I24: EI | J24: =IF(I24="ILF",IF($C$1="预估功能点",'模板使用说明&基础参数'!$E$15,'模板使用说明&基础参数'!$E$22),IF(I24="EIF",IF($C$1="预估功能点",'模板使用说明&基础参数'!$E$16,'模板使用说明&基础参数'!$E$23),IF(I24="EI",IF($C$1="预估功能点",'模板使用说明&基础参数'!$E$17,'模板使用说明&基础参数'!$E$24),IF(I24="EO",IF($C$1="预估功能点",'模板使用说明&基础参数'!$E$18,'模板使用说明&基础参数'!$E$25),IF(I24="EQ",IF($C$1="预估功能点",'模板使用说明&基础参数'!$E$19,'模板使用说明&基础参数'!$E$26),""))))) -> 4 | K24: 中 | L24: 新增 | M24: =IF(J24="","",IF(K24="高",IF(L24="删除",J24*'模板使用说明&基础参数'!$E$5*'模板使用说明&基础参数'!$E$12,IF(L24="修改",J24*'模板使用说明&基础参数'!$E$5*'模板使用说明&基础参数'!$E$11,J24*'模板使用说明&基础参数'!$E$5*'模板使用说明&基础参数'!$E$10)),IF(K24="中",IF(L24="删除",J24*'模板使用说明&基础参数'!$E$6*'模板使用说明&基础参数'!$E$12,IF(L24="修改",J24*'模板使用说明&基础参数'!$E$6*'模板使用说明&基础参数'!$E$11,J24*'模板使用说明&基础参数'!$E$6*'模板使用说明&基础参数'!$E$10)),IF(L24="删除",J24*'模板使用说明&基础参数'!$E$7*'模板使用说明&基础参数'!$E$12,IF(L24="修改",J24*'模板使用说明&基础参数'!$E$7*'模板使用说明&基础参数'!$E$11,J24*'模板使用说明&基础参数'!$E$7*'模板使用说明&基础参数'!$E$10))))) -> 2.6666667
A25: =ROW()-5 -> 20 | C25: 票据系统新增贴现票据标识自动报送定时任务 | G25: 在贴现签收后，票据系统新增定时任务对打标的票据信息实现自动报送票交所的功能 | H25: 贴现票据标识自动报送 | I25: EI | J25: =IF(I25="ILF",IF($C$1="预估功能点",'模板使用说明&基础参数'!$E$15,'模板使用说明&基础参数'!$E$22),IF(I25="EIF",IF($C$1="预估功能点",'模板使用说明&基础参数'!$E$16,'模板使用说明&基础参数'!$E$23),IF(I25="EI",IF($C$1="预估功能点",'模板使用说明&基础参数'!$E$17,'模板使用说明&基础参数'!$E$24),IF(I25="EO",IF($C$1="预估功能点",'模板使用说明&基础参数'!$E$18,'模板使用说明&基础参数'!$E$25),IF(I25="EQ",IF($C$1="预估功能点",'模板使用说明&基础参数'!$E$19,'模板使用说明&基础参数'!$E$26),""))))) -> 4 | K25: 中 | L25: 新增 | M25: =IF(J25="","",IF(K25="高",IF(L25="删除",J25*'模板使用说明&基础参数'!$E$5*'模板使用说明&基础参数'!$E$12,IF(L25="修改",J25*'模板使用说明&基础参数'!$E$5*'模板使用说明&基础参数'!$E$11,J25*'模板使用说明&基础参数'!$E$5*'模板使用说明&基础参数'!$E$10)),IF(K25="中",IF(L25="删除",J25*'模板使用说明&基础参数'!$E$6*'模板使用说明&基础参数'!$E$12,IF(L25="修改",J25*'模板使用说明&基础参数'!$E$6*'模板使用说明&基础参数'!$E$11,J25*'模板使用说明&基础参数'!$E$6*'模板使用说明&基础参数'!$E$10)),IF(L25="删除",J25*'模板使用说明&基础参数'!$E$7*'模板使用说明&基础参数'!$E$12,IF(L25="修改",J25*'模板使用说明&基础参数'!$E$7*'模板使用说明&基础参数'!$E$11,J25*'模板使用说明&基础参数'!$E$7*'模板使用说明&基础参数'!$E$10))))) -> 2.6666667
A26: =ROW()-5 -> 21 | C26: 票据系统新增贴现票据标识跟踪查询功能 | G26: 票据系统新增贴现票据标识跟踪查询功能，票据标识跟踪界面-查询出票和贴现票据的票据标识 | H26: 贴现票据标识跟踪查询 | I26: EQ | J26: =IF(I26="ILF",IF($C$1="预估功能点",'模板使用说明&基础参数'!$E$15,'模板使用说明&基础参数'!$E$22),IF(I26="EIF",IF($C$1="预估功能点",'模板使用说明&基础参数'!$E$16,'模板使用说明&基础参数'!$E$23),IF(I26="EI",IF($C$1="预估功能点",'模板使用说明&基础参数'!$E$17,'模板使用说明&基础参数'!$E$24),IF(I26="EO",IF($C$1="预估功能点",'模板使用说明&基础参数'!$E$18,'模板使用说明&基础参数'!$E$25),IF(I26="EQ",IF($C$1="预估功能点",'模板使用说明&基础参数'!$E$19,'模板使用说明&基础参数'!$E$26),""))))) -> 4 | K26: 中 | L26: 新增 | M26: =IF(J26="","",IF(K26="高",IF(L26="删除",J26*'模板使用说明&基础参数'!$E$5*'模板使用说明&基础参数'!$E$12,IF(L26="修改",J26*'模板使用说明&基础参数'!$E$5*'模板使用说明&基础参数'!$E$11,J26*'模板使用说明&基础参数'!$E$5*'模板使用说明&基础参数'!$E$10)),IF(K26="中",IF(L26="删除",J26*'模板使用说明&基础参数'!$E$6*'模板使用说明&基础参数'!$E$12,IF(L26="修改",J26*'模板使用说明&基础参数'!$E$6*'模板使用说明&基础参数'!$E$11,J26*'模板使用说明&基础参数'!$E$6*'模板使用说明&基础参数'!$E$10)),IF(L26="删除",J26*'模板使用说明&基础参数'!$E$7*'模板使用说明&基础参数'!$E$12,IF(L26="修改",J26*'模板使用说明&基础参数'!$E$7*'模板使用说明&基础参数'!$E$11,J26*'模板使用说明&基础参数'!$E$7*'模板使用说明&基础参数'!$E$10))))) -> 2.6666667
A27: =ROW()-5 -> 22 | C27: 票据系统新增存量票据票据标识录入功能 | G27: 票据系统新增存量票据票据标识录入功能，实现对存量票据进行打标功能 | H27: 存量票据票据标识录入 | I27: EI | J27: =IF(I27="ILF",IF($C$1="预估功能点",'模板使用说明&基础参数'!$E$15,'模板使用说明&基础参数'!$E$22),IF(I27="EIF",IF($C$1="预估功能点",'模板使用说明&基础参数'!$E$16,'模板使用说明&基础参数'!$E$23),IF(I27="EI",IF($C$1="预估功能点",'模板使用说明&基础参数'!$E$17,'模板使用说明&基础参数'!$E$24),IF(I27="EO",IF($C$1="预估功能点",'模板使用说明&基础参数'!$E$18,'模板使用说明&基础参数'!$E$25),IF(I27="EQ",IF($C$1="预估功能点",'模板使用说明&基础参数'!$E$19,'模板使用说明&基础参数'!$E$26),""))))) -> 4 | K27: 中 | L27: 新增 | M27: =IF(J27="","",IF(K27="高",IF(L27="删除",J27*'模板使用说明&基础参数'!$E$5*'模板使用说明&基础参数'!$E$12,IF(L27="修改",J27*'模板使用说明&基础参数'!$E$5*'模板使用说明&基础参数'!$E$11,J27*'模板使用说明&基础参数'!$E$5*'模板使用说明&基础参数'!$E$10)),IF(K27="中",IF(L27="删除",J27*'模板使用说明&基础参数'!$E$6*'模板使用说明&基础参数'!$E$12,IF(L27="修改",J27*'模板使用说明&基础参数'!$E$6*'模板使用说明&基础参数'!$E$11,J27*'模板使用说明&基础参数'!$E$6*'模板使用说明&基础参数'!$E$10)),IF(L27="删除",J27*'模板使用说明&基础参数'!$E$7*'模板使用说明&基础参数'!$E$12,IF(L27="修改",J27*'模板使用说明&基础参数'!$E$7*'模板使用说明&基础参数'!$E$11,J27*'模板使用说明&基础参数'!$E$7*'模板使用说明&基础参数'!$E$10))))) -> 2.6666667
A28: =ROW()-5 -> 23 | C28: 票据系统新增出票票据标识查询功能 | G28: 票据系统新增出票标识查询功能，对已经维护的票据标识票据进行查询功能 | H28: 出票票据标识查询 | I28: EQ | J28: =IF(I28="ILF",IF($C$1="预估功能点",'模板使用说明&基础参数'!$E$15,'模板使用说明&基础参数'!$E$22),IF(I28="EIF",IF($C$1="预估功能点",'模板使用说明&基础参数'!$E$16,'模板使用说明&基础参数'!$E$23),IF(I28="EI",IF($C$1="预估功能点",'模板使用说明&基础参数'!$E$17,'模板使用说明&基础参数'!$E$24),IF(I28="EO",IF($C$1="预估功能点",'模板使用说明&基础参数'!$E$18,'模板使用说明&基础参数'!$E$25),IF(I28="EQ",IF($C$1="预估功能点",'模板使用说明&基础参数'!$E$19,'模板使用说明&基础参数'!$E$26),""))))) -> 4 | K28: 中 | L28: 新增 | M28: =IF(J28="","",IF(K28="高",IF(L28="删除",J28*'模板使用说明&基础参数'!$E$5*'模板使用说明&基础参数'!$E$12,IF(L28="修改",J28*'模板使用说明&基础参数'!$E$5*'模板使用说明&基础参数'!$E$11,J28*'模板使用说明&基础参数'!$E$5*'模板使用说明&基础参数'!$E$10)),IF(K28="中",IF(L28="删除",J28*'模板使用说明&基础参数'!$E$6*'模板使用说明&基础参数'!$E$12,IF(L28="修改",J28*'模板使用说明&基础参数'!$E$6*'模板使用说明&基础参数'!$E$11,J28*'模板使用说明&基础参数'!$E$6*'模板使用说明&基础参数'!$E$10)),IF(L28="删除",J28*'模板使用说明&基础参数'!$E$7*'模板使用说明&基础参数'!$E$12,IF(L28="修改",J28*'模板使用说明&基础参数'!$E$7*'模板使用说明&基础参数'!$E$11,J28*'模板使用说明&基础参数'!$E$7*'模板使用说明&基础参数'!$E$10))))) -> 2.6666667
A29: =ROW()-5 -> 24 | C29: 票据系统新增产业属性信息解析功能 | G29: 票据系统新增产业属性信息解析功能 | H29: 产业属性信息解析保存 | I29: EI | J29: =IF(I29="ILF",IF($C$1="预估功能点",'模板使用说明&基础参数'!$E$15,'模板使用说明&基础参数'!$E$22),IF(I29="EIF",IF($C$1="预估功能点",'模板使用说明&基础参数'!$E$16,'模板使用说明&基础参数'!$E$23),IF(I29="EI",IF($C$1="预估功能点",'模板使用说明&基础参数'!$E$17,'模板使用说明&基础参数'!$E$24),IF(I29="EO",IF($C$1="预估功能点",'模板使用说明&基础参数'!$E$18,'模板使用说明&基础参数'!$E$25),IF(I29="EQ",IF($C$1="预估功能点",'模板使用说明&基础参数'!$E$19,'模板使用说明&基础参数'!$E$26),""))))) -> 4 | K29: 低 | L29: 新增 | M29: =IF(J29="","",IF(K29="高",IF(L29="删除",J29*'模板使用说明&基础参数'!$E$5*'模板使用说明&基础参数'!$E$12,IF(L29="修改",J29*'模板使用说明&基础参数'!$E$5*'模板使用说明&基础参数'!$E$11,J29*'模板使用说明&基础参数'!$E$5*'模板使用说明&基础参数'!$E$10)),IF(K29="中",IF(L29="删除",J29*'模板使用说明&基础参数'!$E$6*'模板使用说明&基础参数'!$E$12,IF(L29="修改",J29*'模板使用说明&基础参数'!$E$6*'模板使用说明&基础参数'!$E$11,J29*'模板使用说明&基础参数'!$E$6*'模板使用说明&基础参数'!$E$10)),IF(L29="删除",J29*'模板使用说明&基础参数'!$E$7*'模板使用说明&基础参数'!$E$12,IF(L29="修改",J29*'模板使用说明&基础参数'!$E$7*'模板使用说明&基础参数'!$E$11,J29*'模板使用说明&基础参数'!$E$7*'模板使用说明&基础参数'!$E$10))))) -> 4
A30: =ROW()-5 -> 25 | G30: 对票交所下发的cim025报文信息保存在票据产业属性信息登记信息表 | J30: =IF(I30="ILF",IF($C$1="预估功能点",'模板使用说明&基础参数'!$E$15,'模板使用说明&基础参数'!$E$22),IF(I30="EIF",IF($C$1="预估功能点",'模板使用说明&基础参数'!$E$16,'模板使用说明&基础参数'!$E$23),IF(I30="EI",IF($C$1="预估功能点",'模板使用说明&基础参数'!$E$17,'模板使用说明&基础参数'!$E$24),IF(I30="EO",IF($C$1="预估功能点",'模板使用说明&基础参数'!$E$18,'模板使用说明&基础参数'!$E$25),IF(I30="EQ",IF($C$1="预估功能点",'模板使用说明&基础参数'!$E$19,'模板使用说明&基础参数'!$E$26),""))))) | M30: =IF(J30="","",IF(K30="高",IF(L30="删除",J30*'模板使用说明&基础参数'!$E$5*'模板使用说明&基础参数'!$E$12,IF(L30="修改",J30*'模板使用说明&基础参数'!$E$5*'模板使用说明&基础参数'!$E$11,J30*'模板使用说明&基础参数'!$E$5*'模板使用说明&基础参数'!$E$10)),IF(K30="中",IF(L30="删除",J30*'模板使用说明&基础参数'!$E$6*'模板使用说明&基础参数'!$E$12,IF(L30="修改",J30*'模板使用说明&基础参数'!$E$6*'模板使用说明&基础参数'!$E$11,J30*'模板使用说明&基础参数'!$E$6*'模板使用说明&基础参数'!$E$10)),IF(L30="删除",J30*'模板使用说明&基础参数'!$E$7*'模板使用说明&基础参数'!$E$12,IF(L30="修改",J30*'模板使用说明&基础参数'!$E$7*'模板使用说明&基础参数'!$E$11,J30*'模板使用说明&基础参数'!$E$7*'模板使用说明&基础参数'!$E$10))))) | N30: 已识别
A31: =ROW()-5 -> 26 | C31: 票据系统新增产业属性信息查询功能 | G31: 票据系统新增产业属性信息查询功能，对票交所下发的产业属性信息进行展示 | H31: 产业属性信息查询 | I31: EQ | J31: =IF(I31="ILF",IF($C$1="预估功能点",'模板使用说明&基础参数'!$E$15,'模板使用说明&基础参数'!$E$22),IF(I31="EIF",IF($C$1="预估功能点",'模板使用说明&基础参数'!$E$16,'模板使用说明&基础参数'!$E$23),IF(I31="EI",IF($C$1="预估功能点",'模板使用说明&基础参数'!$E$17,'模板使用说明&基础参数'!$E$24),IF(I31="EO",IF($C$1="预估功能点",'模板使用说明&基础参数'!$E$18,'模板使用说明&基础参数'!$E$25),IF(I31="EQ",IF($C$1="预估功能点",'模板使用说明&基础参数'!$E$19,'模板使用说明&基础参数'!$E$26),""))))) -> 4 | K31: 低 | L31: 新增 | M31: =IF(J31="","",IF(K31="高",IF(L31="删除",J31*'模板使用说明&基础参数'!$E$5*'模板使用说明&基础参数'!$E$12,IF(L31="修改",J31*'模板使用说明&基础参数'!$E$5*'模板使用说明&基础参数'!$E$11,J31*'模板使用说明&基础参数'!$E$5*'模板使用说明&基础参数'!$E$10)),IF(K31="中",IF(L31="删除",J31*'模板使用说明&基础参数'!$E$6*'模板使用说明&基础参数'!$E$12,IF(L31="修改",J31*'模板使用说明&基础参数'!$E$6*'模板使用说明&基础参数'!$E$11,J31*'模板使用说明&基础参数'!$E$6*'模板使用说明&基础参数'!$E$10)),IF(L31="删除",J31*'模板使用说明&基础参数'!$E$7*'模板使用说明&基础参数'!$E$12,IF(L31="修改",J31*'模板使用说明&基础参数'!$E$7*'模板使用说明&基础参数'!$E$11,J31*'模板使用说明&基础参数'!$E$7*'模板使用说明&基础参数'!$E$10))))) -> 4
A32: =ROW()-5 -> 27 | B32: 数据报送平台 | C32: 数据报送平台《存量科技贷款信息》相关改造功能 | G32: 数据报送平台修改数据加工口径，统计相关业务数据信息，《存量科技贷款信息》中是否为科技贷款以及各项科技贷款分类需从信贷系统进行获取 | H32: 《存量科技贷款信息》报表 | I32: EO | J32: =IF(I32="ILF",IF($C$1="预估功能点",'模板使用说明&基础参数'!$E$15,'模板使用说明&基础参数'!$E$22),IF(I32="EIF",IF($C$1="预估功能点",'模板使用说明&基础参数'!$E$16,'模板使用说明&基础参数'!$E$23),IF(I32="EI",IF($C$1="预估功能点",'模板使用说明&基础参数'!$E$17,'模板使用说明&基础参数'!$E$24),IF(I32="EO",IF($C$1="预估功能点",'模板使用说明&基础参数'!$E$18,'模板使用说明&基础参数'!$E$25),IF(I32="EQ",IF($C$1="预估功能点",'模板使用说明&基础参数'!$E$19,'模板使用说明&基础参数'!$E$26),""))))) -> 5 | K32: 高 | L32: 修改 | M32: =IF(J32="","",IF(K32="高",IF(L32="删除",J32*'模板使用说明&基础参数'!$E$5*'模板使用说明&基础参数'!$E$12,IF(L32="修改",J32*'模板使用说明&基础参数'!$E$5*'模板使用说明&基础参数'!$E$11,J32*'模板使用说明&基础参数'!$E$5*'模板使用说明&基础参数'!$E$10)),IF(K32="中",IF(L32="删除",J32*'模板使用说明&基础参数'!$E$6*'模板使用说明&基础参数'!$E$12,IF(L32="修改",J32*'模板使用说明&基础参数'!$E$6*'模板使用说明&基础参数'!$E$11,J32*'模板使用说明&基础参数'!$E$6*'模板使用说明&基础参数'!$E$10)),IF(L32="删除",J32*'模板使用说明&基础参数'!$E$7*'模板使用说明&基础参数'!$E$12,IF(L32="修改",J32*'模板使用说明&基础参数'!$E$7*'模板使用说明&基础参数'!$E$11,J32*'模板使用说明&基础参数'!$E$7*'模板使用说明&基础参数'!$E$10))))) -> 1.3333333
A33: =ROW()-5 -> 28 | G33: 系统前台根据修订内容相应调整删除、新增、修改、删除、详情、提交审批、下载EXCEL、导入数据、按照报送要素多维度查询修改、批量校验、精准校验、数据打包、数据报送功能 | H33: 《存量科技贷款信息》报表数据信息 | I33: ILF | J33: =IF(I33="ILF",IF($C$1="预估功能点",'模板使用说明&基础参数'!$E$15,'模板使用说明&基础参数'!$E$22),IF(I33="EIF",IF($C$1="预估功能点",'模板使用说明&基础参数'!$E$16,'模板使用说明&基础参数'!$E$23),IF(I33="EI",IF($C$1="预估功能点",'模板使用说明&基础参数'!$E$17,'模板使用说明&基础参数'!$E$24),IF(I33="EO",IF($C$1="预估功能点",'模板使用说明&基础参数'!$E$18,'模板使用说明&基础参数'!$E$25),IF(I33="EQ",IF($C$1="预估功能点",'模板使用说明&基础参数'!$E$19,'模板使用说明&基础参数'!$E$26),""))))) -> 10 | K33: 高 | L33: 修改 | M33: =IF(J33="","",IF(K33="高",IF(L33="删除",J33*'模板使用说明&基础参数'!$E$5*'模板使用说明&基础参数'!$E$12,IF(L33="修改",J33*'模板使用说明&基础参数'!$E$5*'模板使用说明&基础参数'!$E$11,J33*'模板使用说明&基础参数'!$E$5*'模板使用说明&基础参数'!$E$10)),IF(K33="中",IF(L33="删除",J33*'模板使用说明&基础参数'!$E$6*'模板使用说明&基础参数'!$E$12,IF(L33="修改",J33*'模板使用说明&基础参数'!$E$6*'模板使用说明&基础参数'!$E$11,J33*'模板使用说明&基础参数'!$E$6*'模板使用说明&基础参数'!$E$10)),IF(L33="删除",J33*'模板使用说明&基础参数'!$E$7*'模板使用说明&基础参数'!$E$12,IF(L33="修改",J33*'模板使用说明&基础参数'!$E$7*'模板使用说明&基础参数'!$E$11,J33*'模板使用说明&基础参数'!$E$7*'模板使用说明&基础参数'!$E$10))))) -> 2.6666667
A34: =ROW()-5 -> 29 | C34: 数据报送平台《科技贷款发生额信息》相关改造功能 | G34: 数据报送平台修改数据加工口径，统计相关业务数据信息，《科技贷款发生额信息》中是否为科技贷款以及各项科技贷款分类需从信贷系统进行获取 | H34: 《科技贷款发生额信息》报表 | I34: EO | J34: =IF(I34="ILF",IF($C$1="预估功能点",'模板使用说明&基础参数'!$E$15,'模板使用说明&基础参数'!$E$22),IF(I34="EIF",IF($C$1="预估功能点",'模板使用说明&基础参数'!$E$16,'模板使用说明&基础参数'!$E$23),IF(I34="EI",IF($C$1="预估功能点",'模板使用说明&基础参数'!$E$17,'模板使用说明&基础参数'!$E$24),IF(I34="EO",IF($C$1="预估功能点",'模板使用说明&基础参数'!$E$18,'模板使用说明&基础参数'!$E$25),IF(I34="EQ",IF($C$1="预估功能点",'模板使用说明&基础参数'!$E$19,'模板使用说明&基础参数'!$E$26),""))))) -> 5 | K34: 高 | L34: 修改 | M34: =IF(J34="","",IF(K34="高",IF(L34="删除",J34*'模板使用说明&基础参数'!$E$5*'模板使用说明&基础参数'!$E$12,IF(L34="修改",J34*'模板使用说明&基础参数'!$E$5*'模板使用说明&基础参数'!$E$11,J34*'模板使用说明&基础参数'!$E$5*'模板使用说明&基础参数'!$E$10)),IF(K34="中",IF(L34="删除",J34*'模板使用说明&基础参数'!$E$6*'模板使用说明&基础参数'!$E$12,IF(L34="修改",J34*'模板使用说明&基础参数'!$E$6*'模板使用说明&基础参数'!$E$11,J34*'模板使用说明&基础参数'!$E$6*'模板使用说明&基础参数'!$E$10)),IF(L34="删除",J34*'模板使用说明&基础参数'!$E$7*'模板使用说明&基础参数'!$E$12,IF(L34="修改",J34*'模板使用说明&基础参数'!$E$7*'模板使用说明&基础参数'!$E$11,J34*'模板使用说明&基础参数'!$E$7*'模板使用说明&基础参数'!$E$10))))) -> 1.3333333
A35: =ROW()-5 -> 30 | G35: 系统前台根据修订内容相应调整删除、新增、修改、删除、详情、提交审批、下载EXCEL、导入数据、按照报送要素多维度查询修改、批量校验、精准校验、数据打包、数据报送功能 | H35: 《科技贷款发生额信息》报表数据信息 | I35: ILF | J35: =IF(I35="ILF",IF($C$1="预估功能点",'模板使用说明&基础参数'!$E$15,'模板使用说明&基础参数'!$E$22),IF(I35="EIF",IF($C$1="预估功能点",'模板使用说明&基础参数'!$E$16,'模板使用说明&基础参数'!$E$23),IF(I35="EI",IF($C$1="预估功能点",'模板使用说明&基础参数'!$E$17,'模板使用说明&基础参数'!$E$24),IF(I35="EO",IF($C$1="预估功能点",'模板使用说明&基础参数'!$E$18,'模板使用说明&基础参数'!$E$25),IF(I35="EQ",IF($C$1="预估功能点",'模板使用说明&基础参数'!$E$19,'模板使用说明&基础参数'!$E$26),""))))) -> 10 | K35: 高 | L35: 修改 | M35: =IF(J35="","",IF(K35="高",IF(L35="删除",J35*'模板使用说明&基础参数'!$E$5*'模板使用说明&基础参数'!$E$12,IF(L35="修改",J35*'模板使用说明&基础参数'!$E$5*'模板使用说明&基础参数'!$E$11,J35*'模板使用说明&基础参数'!$E$5*'模板使用说明&基础参数'!$E$10)),IF(K35="中",IF(L35="删除",J35*'模板使用说明&基础参数'!$E$6*'模板使用说明&基础参数'!$E$12,IF(L35="修改",J35*'模板使用说明&基础参数'!$E$6*'模板使用说明&基础参数'!$E$11,J35*'模板使用说明&基础参数'!$E$6*'模板使用说明&基础参数'!$E$10)),IF(L35="删除",J35*'模板使用说明&基础参数'!$E$7*'模板使用说明&基础参数'!$E$12,IF(L35="修改",J35*'模板使用说明&基础参数'!$E$7*'模板使用说明&基础参数'!$E$11,J35*'模板使用说明&基础参数'!$E$7*'模板使用说明&基础参数'!$E$10))))) -> 2.6666667
A36: =ROW()-5 -> 31 | C36: 数据报送平台《存量数字经济产业贷款信息》相关改造功能 | G36: 数据报送平台修改数据加工口径，统计相关业务数据信息，《存量数字经济产业贷款信息》中是否为数字经济产业贷款需从信贷系统进行获取 | H36: 《存量数字经济产业贷款信息》报表 | I36: EO | J36: =IF(I36="ILF",IF($C$1="预估功能点",'模板使用说明&基础参数'!$E$15,'模板使用说明&基础参数'!$E$22),IF(I36="EIF",IF($C$1="预估功能点",'模板使用说明&基础参数'!$E$16,'模板使用说明&基础参数'!$E$23),IF(I36="EI",IF($C$1="预估功能点",'模板使用说明&基础参数'!$E$17,'模板使用说明&基础参数'!$E$24),IF(I36="EO",IF($C$1="预估功能点",'模板使用说明&基础参数'!$E$18,'模板使用说明&基础参数'!$E$25),IF(I36="EQ",IF($C$1="预估功能点",'模板使用说明&基础参数'!$E$19,'模板使用说明&基础参数'!$E$26),""))))) -> 5 | K36: 高 | L36: 修改 | M36: =IF(J36="","",IF(K36="高",IF(L36="删除",J36*'模板使用说明&基础参数'!$E$5*'模板使用说明&基础参数'!$E$12,IF(L36="修改",J36*'模板使用说明&基础参数'!$E$5*'模板使用说明&基础参数'!$E$11,J36*'模板使用说明&基础参数'!$E$5*'模板使用说明&基础参数'!$E$10)),IF(K36="中",IF(L36="删除",J36*'模板使用说明&基础参数'!$E$6*'模板使用说明&基础参数'!$E$12,IF(L36="修改",J36*'模板使用说明&基础参数'!$E$6*'模板使用说明&基础参数'!$E$11,J36*'模板使用说明&基础参数'!$E$6*'模板使用说明&基础参数'!$E$10)),IF(L36="删除",J36*'模板使用说明&基础参数'!$E$7*'模板使用说明&基础参数'!$E$12,IF(L36="修改",J36*'模板使用说明&基础参数'!$E$7*'模板使用说明&基础参数'!$E$11,J36*'模板使用说明&基础参数'!$E$7*'模板使用说明&基础参数'!$E$10))))) -> 1.3333333
A37: =ROW()-5 -> 32 | G37: 系统前台根据修订内容相应调整删除、新增、修改、删除、详情、提交审批、下载EXCEL、导入数据、按照报送要素多维度查询修改、批量校验、精准校验、数据打包、数据报送功能 | H37: 《存量数字经济产业贷款信息》报表数据信息 | I37: ILF | J37: =IF(I37="ILF",IF($C$1="预估功能点",'模板使用说明&基础参数'!$E$15,'模板使用说明&基础参数'!$E$22),IF(I37="EIF",IF($C$1="预估功能点",'模板使用说明&基础参数'!$E$16,'模板使用说明&基础参数'!$E$23),IF(I37="EI",IF($C$1="预估功能点",'模板使用说明&基础参数'!$E$17,'模板使用说明&基础参数'!$E$24),IF(I37="EO",IF($C$1="预估功能点",'模板使用说明&基础参数'!$E$18,'模板使用说明&基础参数'!$E$25),IF(I37="EQ",IF($C$1="预估功能点",'模板使用说明&基础参数'!$E$19,'模板使用说明&基础参数'!$E$26),""))))) -> 10 | K37: 高 | L37: 修改 | M37: =IF(J37="","",IF(K37="高",IF(L37="删除",J37*'模板使用说明&基础参数'!$E$5*'模板使用说明&基础参数'!$E$12,IF(L37="修改",J37*'模板使用说明&基础参数'!$E$5*'模板使用说明&基础参数'!$E$11,J37*'模板使用说明&基础参数'!$E$5*'模板使用说明&基础参数'!$E$10)),IF(K37="中",IF(L37="删除",J37*'模板使用说明&基础参数'!$E$6*'模板使用说明&基础参数'!$E$12,IF(L37="修改",J37*'模板使用说明&基础参数'!$E$6*'模板使用说明&基础参数'!$E$11,J37*'模板使用说明&基础参数'!$E$6*'模板使用说明&基础参数'!$E$10)),IF(L37="删除",J37*'模板使用说明&基础参数'!$E$7*'模板使用说明&基础参数'!$E$12,IF(L37="修改",J37*'模板使用说明&基础参数'!$E$7*'模板使用说明&基础参数'!$E$11,J37*'模板使用说明&基础参数'!$E$7*'模板使用说明&基础参数'!$E$10))))) -> 2.6666667
A38: =ROW()-5 -> 33 | C38: 数据报送平台《数字经济产业贷款发生额信息》相关改造功能 | G38: 数据报送平台修改数据加工口径，统计相关业务数据信息，《数字经济产业贷款发生额信息》中是否为数字经济产业贷款需从信贷系统进行获取 | H38: 《数字经济产业贷款发生额信息》报表 | I38: EO | J38: =IF(I38="ILF",IF($C$1="预估功能点",'模板使用说明&基础参数'!$E$15,'模板使用说明&基础参数'!$E$22),IF(I38="EIF",IF($C$1="预估功能点",'模板使用说明&基础参数'!$E$16,'模板使用说明&基础参数'!$E$23),IF(I38="EI",IF($C$1="预估功能点",'模板使用说明&基础参数'!$E$17,'模板使用说明&基础参数'!$E$24),IF(I38="EO",IF($C$1="预估功能点",'模板使用说明&基础参数'!$E$18,'模板使用说明&基础参数'!$E$25),IF(I38="EQ",IF($C$1="预估功能点",'模板使用说明&基础参数'!$E$19,'模板使用说明&基础参数'!$E$26),""))))) -> 5 | K38: 高 | L38: 修改 | M38: =IF(J38="","",IF(K38="高",IF(L38="删除",J38*'模板使用说明&基础参数'!$E$5*'模板使用说明&基础参数'!$E$12,IF(L38="修改",J38*'模板使用说明&基础参数'!$E$5*'模板使用说明&基础参数'!$E$11,J38*'模板使用说明&基础参数'!$E$5*'模板使用说明&基础参数'!$E$10)),IF(K38="中",IF(L38="删除",J38*'模板使用说明&基础参数'!$E$6*'模板使用说明&基础参数'!$E$12,IF(L38="修改",J38*'模板使用说明&基础参数'!$E$6*'模板使用说明&基础参数'!$E$11,J38*'模板使用说明&基础参数'!$E$6*'模板使用说明&基础参数'!$E$10)),IF(L38="删除",J38*'模板使用说明&基础参数'!$E$7*'模板使用说明&基础参数'!$E$12,IF(L38="修改",J38*'模板使用说明&基础参数'!$E$7*'模板使用说明&基础参数'!$E$11,J38*'模板使用说明&基础参数'!$E$7*'模板使用说明&基础参数'!$E$10))))) -> 1.3333333
A39: =ROW()-5 -> 34 | G39: 系统前台根据修订内容相应调整删除、新增、修改、删除、详情、提交审批、下载EXCEL、导入数据、按照报送要素多维度查询修改、批量校验、精准校验、数据打包、数据报送功能 | H39: 《数字经济产业贷款发生额信息》报表数据信息 | I39: ILF | J39: =IF(I39="ILF",IF($C$1="预估功能点",'模板使用说明&基础参数'!$E$15,'模板使用说明&基础参数'!$E$22),IF(I39="EIF",IF($C$1="预估功能点",'模板使用说明&基础参数'!$E$16,'模板使用说明&基础参数'!$E$23),IF(I39="EI",IF($C$1="预估功能点",'模板使用说明&基础参数'!$E$17,'模板使用说明&基础参数'!$E$24),IF(I39="EO",IF($C$1="预估功能点",'模板使用说明&基础参数'!$E$18,'模板使用说明&基础参数'!$E$25),IF(I39="EQ",IF($C$1="预估功能点",'模板使用说明&基础参数'!$E$19,'模板使用说明&基础参数'!$E$26),""))))) -> 10 | K39: 高 | L39: 修改 | M39: =IF(J39="","",IF(K39="高",IF(L39="删除",J39*'模板使用说明&基础参数'!$E$5*'模板使用说明&基础参数'!$E$12,IF(L39="修改",J39*'模板使用说明&基础参数'!$E$5*'模板使用说明&基础参数'!$E$11,J39*'模板使用说明&基础参数'!$E$5*'模板使用说明&基础参数'!$E$10)),IF(K39="中",IF(L39="删除",J39*'模板使用说明&基础参数'!$E$6*'模板使用说明&基础参数'!$E$12,IF(L39="修改",J39*'模板使用说明&基础参数'!$E$6*'模板使用说明&基础参数'!$E$11,J39*'模板使用说明&基础参数'!$E$6*'模板使用说明&基础参数'!$E$10)),IF(L39="删除",J39*'模板使用说明&基础参数'!$E$7*'模板使用说明&基础参数'!$E$12,IF(L39="修改",J39*'模板使用说明&基础参数'!$E$7*'模板使用说明&基础参数'!$E$11,J39*'模板使用说明&基础参数'!$E$7*'模板使用说明&基础参数'!$E$10))))) -> 2.6666667
A40: =ROW()-5 -> 35 | C40: 数据报送平台《存量专项贷款信息_山东》相关改造功能 | G40: 数据报送平台修改数据加工口径，统计相关业务数据信息，《存量专项贷款信息_山东》中是否为数字经济产业贷款、是否为科技贷款以及各项科技贷款分类需从信贷系统进行获取 | H40: 《存量专项贷款信息_山东》报表 | I40: EO | J40: =IF(I40="ILF",IF($C$1="预估功能点",'模板使用说明&基础参数'!$E$15,'模板使用说明&基础参数'!$E$22),IF(I40="EIF",IF($C$1="预估功能点",'模板使用说明&基础参数'!$E$16,'模板使用说明&基础参数'!$E$23),IF(I40="EI",IF($C$1="预估功能点",'模板使用说明&基础参数'!$E$17,'模板使用说明&基础参数'!$E$24),IF(I40="EO",IF($C$1="预估功能点",'模板使用说明&基础参数'!$E$18,'模板使用说明&基础参数'!$E$25),IF(I40="EQ",IF($C$1="预估功能点",'模板使用说明&基础参数'!$E$19,'模板使用说明&基础参数'!$E$26),""))))) -> 5 | K40: 高 | L40: 修改 | M40: =IF(J40="","",IF(K40="高",IF(L40="删除",J40*'模板使用说明&基础参数'!$E$5*'模板使用说明&基础参数'!$E$12,IF(L40="修改",J40*'模板使用说明&基础参数'!$E$5*'模板使用说明&基础参数'!$E$11,J40*'模板使用说明&基础参数'!$E$5*'模板使用说明&基础参数'!$E$10)),IF(K40="中",IF(L40="删除",J40*'模板使用说明&基础参数'!$E$6*'模板使用说明&基础参数'!$E$12,IF(L40="修改",J40*'模板使用说明&基础参数'!$E$6*'模板使用说明&基础参数'!$E$11,J40*'模板使用说明&基础参数'!$E$6*'模板使用说明&基础参数'!$E$10)),IF(L40="删除",J40*'模板使用说明&基础参数'!$E$7*'模板使用说明&基础参数'!$E$12,IF(L40="修改",J40*'模板使用说明&基础参数'!$E$7*'模板使用说明&基础参数'!$E$11,J40*'模板使用说明&基础参数'!$E$7*'模板使用说明&基础参数'!$E$10))))) -> 1.3333333
A41: =ROW()-5 -> 36 | G41: 系统前台根据修订内容相应调整删除、新增、修改、删除、详情、提交审批、下载EXCEL、导入数据、按照报送要素多维度查询修改、批量校验、精准校验、数据打包、数据报送功能 | H41: 《存量专项贷款信息_山东》报表数据信息 | I41: ILF | J41: =IF(I41="ILF",IF($C$1="预估功能点",'模板使用说明&基础参数'!$E$15,'模板使用说明&基础参数'!$E$22),IF(I41="EIF",IF($C$1="预估功能点",'模板使用说明&基础参数'!$E$16,'模板使用说明&基础参数'!$E$23),IF(I41="EI",IF($C$1="预估功能点",'模板使用说明&基础参数'!$E$17,'模板使用说明&基础参数'!$E$24),IF(I41="EO",IF($C$1="预估功能点",'模板使用说明&基础参数'!$E$18,'模板使用说明&基础参数'!$E$25),IF(I41="EQ",IF($C$1="预估功能点",'模板使用说明&基础参数'!$E$19,'模板使用说明&基础参数'!$E$26),""))))) -> 10 | K41: 高 | L41: 修改 | M41: =IF(J41="","",IF(K41="高",IF(L41="删除",J41*'模板使用说明&基础参数'!$E$5*'模板使用说明&基础参数'!$E$12,IF(L41="修改",J41*'模板使用说明&基础参数'!$E$5*'模板使用说明&基础参数'!$E$11,J41*'模板使用说明&基础参数'!$E$5*'模板使用说明&基础参数'!$E$10)),IF(K41="中",IF(L41="删除",J41*'模板使用说明&基础参数'!$E$6*'模板使用说明&基础参数'!$E$12,IF(L41="修改",J41*'模板使用说明&基础参数'!$E$6*'模板使用说明&基础参数'!$E$11,J41*'模板使用说明&基础参数'!$E$6*'模板使用说明&基础参数'!$E$10)),IF(L41="删除",J41*'模板使用说明&基础参数'!$E$7*'模板使用说明&基础参数'!$E$12,IF(L41="修改",J41*'模板使用说明&基础参数'!$E$7*'模板使用说明&基础参数'!$E$11,J41*'模板使用说明&基础参数'!$E$7*'模板使用说明&基础参数'!$E$10))))) -> 2.6666667
...

Sheet 费用估算
A1: 涉及系统 | D1: 多系统 | H1: 说明
D2: 多系统合计 | E2: =规模估算!B6 -> 新一代电子票据系统 | F2: =规模估算!B32 -> 数据报送平台 | G2: =规模估算!B44 -> 信贷系统
A3: 规模估算结果（单位：功能点） | D3: =SUM(E3:G3) -> 105.06667 | E3: =SUM(规模估算!$M6:$M31) -> 64 | F3: =SUM(规模估算!$M32:$M43) -> 24 | G3: =SUM(规模估算!$M44:$M53) -> 17.066667 | H3: 未进行功能吻合度调整
A4: 规模变更调整因子取值 | C4: =项目特征!D1 -> 1.21 | E4: =$C4 -> 1.21 | F4: =$C4 -> 1.21 | G4: =$C4 -> 1.21 | H4: 根据估算时机取值
A5: 调整后规模（单位：功能点） | C5: =C3*C4 -> 0 | D5: =SUM(E5:G5) -> 127.13067 | E5: =E3*E4 -> 77.44 | F5: =F3*F4 -> 29.04 | G5: =G3*G4 -> 20.650667 | J5: 系统分类 | K5: 生产率
A6: 基准生产率（单位：人时/功能点） | C6: =C7*0.8 -> 8.536 | E6: =E7*0.8 -> 8.536 | F6: =F7*0.8 -> 8.536 | G6: =G7*0.8 -> 8.536 | J6: 生产系统 | K6: 10.67
C7: 10.67 | E7: 10.67 | F7: 10.67 | G7: 10.67 | H7: 按照类别选择合适的生产率 | J7: 管理类系统 | K7: 6.83
C8: =C7*1.2 -> 12.804 | E8: =E7*1.2 -> 12.804 | F8: =F7*1.2 -> 12.804 | G8: =G7*1.2 -> 12.804 | J8: ESB | K8: 4.08
A9: 未调整工作量（单位：人天） | C9: =C5*C6/8 -> 0 | D9: =SUM(E9:G9) -> 135.64842 | E9: =E5*E6/8 -> 82.62848 | F9: =F5*F6/8 -> 30.98568 | G9: =G5*G6/8 -> 22.034261 | H9: 下限 | J9: 大数据平台 | K9: 5.55
C10: =C5*C7/8 -> 0 | D10: =SUM(E10:G10) -> 169.56053 | E10: =E5*E7/8 -> 103.2856 | F10: =F5*F7/8 -> 38.7321 | G10: =G5*G7/8 -> 27.542827 | H10: 中值
C11: =C5*C8/8 -> 0 | D11: =SUM(E11:G11) -> 203.47263 | E11: =E5*E8/8 -> 123.94272 | F11: =F5*F8/8 -> 46.47852 | G11: =G5*G8/8 -> 33.051392 | H11: 上限
A12: 调整因子 | B12: 应用类型 | C12: =项目特征!D2 -> 1 | E12: =$C12 -> 1 | F12: =$C12 -> 1 | G12: =$C12 -> 1 | H12: 业务处理系统
B13: 质量特性 | C13: =1+0.025*SUM(项目特征!D3:'项目特征'!D6) -> 1 | E13: =$C13 -> 1 | F13: =$C13 -> 1 | G13: =$C13 -> 1 | H13: 无特别限定
B14: 完整性级别 | C14: =项目特征!D7 -> 1 | E14: =$C14 -> 1 | F14: =$C14 -> 1 | G14: =$C14 -> 1 | H14: 无特别限定
B15: 开发语言 | C15: =项目特征!D8 -> 1 | E15: =$C15 -> 1 | F15: =$C15 -> 1 | G15: =$C15 -> 1 | H15: 无特别限定
B16: 开发团队背景 | C16: =项目特征!D9 -> 0.8 | E16: =$C16 -> 0.8 | F16: =$C16 -> 0.8 | G16: =$C16 -> 0.8 | H16: 无特别限定
B17: 地区因素 | C17: 1 | E17: =$C17 -> 1 | F17: =$C17 -> 1 | G17: =$C17 -> 1 | H17: 地区人员单价系数
A18: 非功能性需求工作量（单位：人天） | C18: 0 | D18: =SUM(E18:G18) -> 0 | E18: 0 | F18: 0 | G18: 0
A19: 调整后项目工作量（单位：人天） | C19: =C9*C12*C13*C14*C15*C16*C17+C18 -> 0 | D19: =SUM(E19:G19) -> 108.51874 | E19: =E9*E12*E13*E14*E15*E16*E17+E18 -> 66.102784 | F19: =F9*F12*F13*F14*F15*F16*F17+F18 -> 24.788544 | G19: =G9*G12*G13*G14*G15*G16*G17+G18 -> 17.627409 | H19: 下限
C20: =C10*C12*C13*C14*C15*C16*C17+C18 -> 0 | D20: =SUM(E20:G20) -> 135.64842 | E20: =E10*E12*E13*E14*E15*E16*E17+E18 -> 82.62848 | F20: =F10*F12*F13*F14*F15*F16*F17+F18 -> 30.98568 | G20: =G10*G12*G13*G14*G15*G16*G17+G18 -> 22.034261 | H20: 中值
C21: =C11*C12*C13*C14*C15*C16*C17+C18 -> 0 | D21: =SUM(E21:G21) -> 162.77811 | E21: =E11*E12*E13*E14*E15*E16*E17+E18 -> 99.154176 | F21: =F11*F12*F13*F14*F15*F16*F17+F18 -> 37.182816 | G21: =G11*G12*G13*G14*G15*G16*G17+G18 -> 26.441114 | H21: 上限
A22: 自主开发工作量（单位：人天） | D22: =SUM(E22:G22) -> 5.28 | E22: 2.2 | F22: 3.08 | G22: 0 | H22: 中值，由技术经理提供
A23: 外包工作量（单位：人天） | D23: =SUM(E23:G23) -> 103.23874 | E23: =E19-E22 -> 63.902784 | F23: =F19-F22 -> 21.708544 | G23: =G19-G22 -> 17.627409 | H23: 下限
D24: =SUM(E24:G24) -> 130.36842 | E24: =E20-E22 -> 80.42848 | F24: =F20-F22 -> 27.90568 | G24: =G20-G22 -> 22.034261 | H24: 中值
D25: =SUM(E25:G25) -> 157.49811 | E25: =E21-E22 -> 96.954176 | F25: =F21-F22 -> 34.102816 | G25: =G21-G22 -> 26.441114 | H25: 上限
A26: 人月基准单价（单位：万元/人月） | C26: 2.57 | E26: 2.57 | F26: 2.57 | G26: 2.57 | H26: 天津银行人月单价，不包含直接非人力成本
A27: 项目费用基准报价（单位：万元） | C27: =C19*C26/22 -> 0 | D27: =SUM(E27:G27) -> 12.676962 | E27: =E19*E26/22 -> 7.722007 | F27: =F19*F26/22 -> 2.8957526 | G27: =G19*G26/22 -> 2.0592019 | H27: 下限，不包含直接非人力成本
C28: =C20*C26/22 -> 0 | D28: =SUM(E28:G28) -> 15.846202 | E28: =E20*E26/22 -> 9.6525088 | F28: =F20*F26/22 -> 3.6196908 | G28: =G20*G26/22 -> 2.5740023 | H28: 中值，不包含直接非人力成本
C29: =C21*C26/22 -> 0 | D29: =SUM(E29:G29) -> 19.015442 | E29: =E21*E26/22 -> 11.583011 | F29: =F21*F26/22 -> 4.343629 | G29: =G21*G26/22 -> 3.0888028 | H29: 上限，不包含直接非人力成本
A30: 外包费用基准报价（单位：万元） | D30: =SUM(E30:G30) -> 12.07 | E30: =ROUND(E23*E26/22,2) -> 7.47 | F30: =ROUND(F23*F26/22,2) -> 2.54 | G30: =ROUND(G23*G26/22,2) -> 2.06 | H30: 下限，不包含直接非人力成本
D31: =SUM(E31:G31) -> 15.23 | E31: =ROUND(E24*E26/22,2) -> 9.4 | F31: =ROUND(F24*F26/22,2) -> 3.26 | G31: =ROUND(G24*G26/22,2) -> 2.57 | H31: 中值，不包含直接非人力成本
D32: =SUM(E32:G32) -> 18.4 | E32: =ROUND(E25*E26/22,2) -> 11.33 | F32: =ROUND(F25*F26/22,2) -> 3.98 | G32: =ROUND(G25*G26/22,2) -> 3.09 | H32: 上限，不包含直接非人力成本

Sheet 模板使用说明&基础参数
A2: 本模板通常只填写白色区域；
A3: 填写顺序为：填写项目特征->规模估算->查看结果（“开发工作量估算”相关部分）
A4: 深灰 | B4: 模板固定部分，不得修改 | D4: 重用程度调整系数
A5: 浅灰 | B5: 模板固定部分，在必要时统一修改 | D5: 高 | E5: 0.33333333
A6: 绿色 | B6: 自动计算或引用数据，不得修改 | D6: 中 | E6: 0.66666667
A7: 白色 | B7: 需填写或修改内容 | D7: 低 | E7: 1
D9: 修改类型调整系数 | G9: 应用类型 | H9: 描述 | I9: 调整因子
D10: 新增 | E10: 1 | G10: 业务处理 | H10: 办公自动化系统、日常管理及业务处理用软件等 | I10: 1
D11: 修改 | E11: 0.8 | G11: 应用集成 | H11: 企业服务总线、应用集成等 | I11: 1.2
D12: 删除 | E12: 0.2 | G12: 科技 | H12: 科学计算、仿真、基于复杂算法的统计分析等 | I12: 1.2
G13: 多媒体 | H13: 多媒体数据处理；地理信息系统；教育和娱乐应用等 | I13: 1.3
D14: 预估功能点 | G14: 智能信息 | H14: 自然语言处理、人工智能、专家系统等 | I14: 1.7
D15: ILF | E15: 35 | G15: 系统软件 | H15: 操作系统、数据库系统、集成开发环境、自动化开发/设计工具等 | I15: 1.7
D16: EIF | E16: 15 | G16: 通信控制 | H16: 通信协议、仿真、交换机软件、全球定位系统等 | I16: 1.9
D17: EI | G17: 流程控制 | H17: 生产管理、仪器控制、机器人控制、实时控制、嵌入式软件等 | I17: 2
D18: EO
D19: EQ | G19: 调整因子 | H19: 判断标准 | I19: 调整因子
G20: 分布式处理 | H20: 没有明示对分布式处理的需求事项 | I20: -1
D21: 估算功能点 | H21: 通过网络进行客户端/服务器及网络基础应用分布处理和传输 | I21: 0
D22: ILF | E22: 10 | H22: 通过特别的设计保证在多个服务器及处理器上同时相互执行应用中的处理功能 | I22: 1
D23: EIF | E23: 7 | G23: 性能 | H23: 没有明示对性能的特别需求事项或仅需提供基本性能 | I23: -1
D24: EI | E24: 4 | H24: 应答时间或处理率对高峰时间或所有业务时间来说都很重要，存在对连动系统结束处理时间的限制 | I24: 0
D25: EO | E25: 5 | H25: 为满足性能需求事项，要求设计阶段开始进行性能分析，或在设计、开发阶段使用分析工具 | I25: 1
D26: EQ | E26: 4 | G26: 可靠性 | H26: 没有明示对可靠性的特别需求事项或仅需提供基本的可靠性 | I26: -1
H27: 发生故障时带来较多不便或经济损失 | I27: 0
H28: 发生故障时造成重大经济损失或有生命危害 | I28: 1
G29: 多重站点 | H29: 在相同的硬件或软件环境下运行 | I29: -1
H30: 在设计阶段需要考虑不同站点的相似硬件或软件环境下运行需求 | I30: 0
H31: 在设计阶段需要考虑不同站点的不同硬件或软件环境下运行需求 | I31: 1
H34: 开发语言 | I34: 调整因子
H35: C及其他同级别语言/平台 | I35: 1.5
H36: JAVA、C++、C#及其他同级别语言/平台 | I36: 1
H37: PowerBuilder、ASP及其他同级别语言/平台 | I37: 0.6
H40: 开发团队背景 | I40: 调整因子
H41: 为本行业开发过类似的软件 | I41: 0.8
H42: 为其他行业开发过类似的软件，或为本行业开发过不同但相关的软件 | I42: 1
H43: 没有同类软件及本行业相关软件开发背景 | I43: 1.2
H45: 完整性级别 | I45: 调整因子
H46: 没有明确的完整性级别或等级为C/D | I46: 1
H47: 完整性级别为A/B同时为达成完整性级别要求采取了特殊的设计及实现方式 | I47: 1.1
...
